Workbook

Sheet Epicas
B3: Epicas
B4: ID_Epica | C4: Nombre
B5: EP-01 | C5: Autenticación y Acceso
B6: EP-02 | C6: Administración Central SIGVE
B7: EP-03 | C7: Gestión de Taller de Mantención
B8: EP-04 | C8: Gestión de Cuartel de Bomberos

Sheet Historias de Usuario
B3: Historias de Usuario
B4: Épica | C4: ID_Historia | D4: Historia de Usuario | E4: Alcance(R) | F4: Impacto(I) | G4: Confianza(C) | H4: Esfuerzo(E) | I4: Puntaje Rice | J4: Prioridad
B5: Autenticación y Acceso | C5: HU 1.1 | D5: Como usuario del sistema quiero poder iniciar y cerrar sesión para acceder a las funcionalidades según mi rol | E5: 10 | F5: 3 | G5: 1.0 | H5: 5 | I5: 6.0 | J5: Alta
B6: Administración Central SIGVE | C6: HU 2.1 | D6: Como Admin SIGVE quiero visualizar un dashboard con estadísticas globales del sistema para tener una visión completa de talleres, cuarteles y vehículos | E6: 5 | F6: 1 | G6: 1.0 | H6: 2 | I6: 2.5 | J6: Media
B7: Administración Central SIGVE | C7: HU 2.2 | D7: Como Admin SIGVE quiero crear un nuevo taller para amplicar la red de mantenimiento | E7: 3 | F7: 2 | G7: 1.0 | H7: 5 | I7: 1.2 | J7: Media
B8: Administración Central SIGVE | C8: HU 2.3 | D8: Como Admin SIGVE quiero gestionar el catálogo de talleres para mantener actualizada la red de mantenimiento | E8: 5 | F8: 1 | G8: 1.0 | H8: 5 | I8: 1.0 | J8: Media
B9: Administración Central SIGVE | C9: HU 2.4 | D9: Como Admin SIGVE quiero editar información de un taller para mantener los datos actualizados | E9: 5 | F9: 2 | G9: 0.8 | H9: 10 | I9: 0.8 | J9: Baja
B10: Administración Central SIGVE | C10: HU 2.5 | D10: Como Admin SIGVE quiero eliminar un taller para remover talleres que ya no operan | E10: 3 | F10: 2 | G10: 1.0 | H10: 2 | I10: 3.0 | J10: Alta
B11: Administración Central SIGVE | C11: HU 2.6 | D11: Como Admin SIGVE quiero crear un nuevo cuartel para registrar nuevas estaciones de bomberos y ampliar la red de cuarteles | E11: 5 | F11: 2 | G11: 1.0 | H11: 5 | I11: 2.0 | J11: Media
B12: Administración Central SIGVE | C12: HU 2.7 | D12: Como Admin SIGVE quiero gestionar el catálogo de cuarteles de bomberos para mantener actualizada la red de cuarteles. | E12: 4 | F12: 2 | G12: 1.0 | H12: 3 | I12: 2.6 | J12: Alta
B13: Administración Central SIGVE | C13: HU 2.8 | D13: Como Admin SIGVE quiero editar información de un cuartel para actualizar sus datos de contexto y ubicación | E13: 5 | F13: 2 | G13: 0.8 | H13: 3 | I13: 2.67 | J13: Media
B14: Administración Central SIGVE | C14: HU 2.9 | D14: Como Admin SIGVE quiero eliminar un cuartel para remover estaciones que ya no están operativas | E14: 5 | F14: 2 | G14: 0.8 | H14: 3 | I14: 2.67 | J14: Alta
B15: Administración Central SIGVE | C15: HU 2.10 | D15: Como Admin SIGVE quiero crear un nuevo repuesto maestros para que este disponible para todos los talleres | E15: 5 | F15: 2 | G15: 0.8 | H15: 5 | I15: 1.6 | J15: Media
B16: Administración Central SIGVE | C16: HU 2.11 | D16: Como Admin SIGVE quiero gestionar el catálogo maestro de repuestos para estandarizar los repuestos disponibles en el sistema | E16: 5 | F16: 2 | G16: 1.0 | H16: 3 | I16: 3.3 | J16: Alta
B17: Administración Central SIGVE | C17: HU 2.12 | D17: Como Admin SIGVE quiero editar un repuesto maestro para actualizar su información | E17: 3 | F17: 2 | G17: 1.0 | H17: 3 | I17: 2.0 | J17: Media
B18: Administración Central SIGVE | C18: HU 2.13 | D18: Como Admin SIGVE quiero eliminar un repuesto maesto para mantener solo repuestos vigentes | E18: 5 | F18: 2 | G18: 0.8 | H18: 3 | I18: 2.67 | J18: Media
B19: Administración Central SIGVE | C19: HU 2.14 | D19: Como Admin SIGVE quiero crear un proveedor global para que todos los talleres puedan usarlo | E19: 5 | F19: 2 | G19: 0.8 | H19: 2 | I19: 4.0 | J19: Alta
B20: Administración Central SIGVE | C20: HU 2.15 | D20: Como Admin SIGVE quiero gestionar el catálogo de proveedores globalres para que esten disponibles parar todos los talleres | E20: 5 | F20: 2 | G20: 1.0 | H20: 5 | I20: 2.0 | J20: Media
B21: Administración Central SIGVE | C21: HU 2.16 | D21: Como Admin SIGVE quiero editar un proveedor global para mantener sus datos actualizados | E21: 5 | F21: 2 | G21: 1.0 | H21: 3 | I21: 3.33 | J21: Alta
B22: Administración Central SIGVE | C22: HU 2.17 | D22: Como Admin SIGVE quiero eliminar un proveedor para mantener solo proveedores activos | E22: 5 | F22: 2 | G22: 0.8 | H22: 2 | I22: 4.0 | J22: Alta
B23: Administración Central SIGVE | C23: HU 2.18 | D23: Como Admin SIGVE quiero crear un item de catálogo para agregar nuevas opciones al sistema | E23: 2 | F23: 2 | G23: 0.8 | H23: 2 | I23: 1.6 | J23: Media
B24: Administración Central SIGVE | C24: HU 2.19 | D24: Como Admin SIGVE quiero gestionar catálogos genéricos del sistema para mantener actualizada las listas de opciones | E24: 1 | F24: 3 | G24: 0.5 | H24: 8 | I24: 0.19 | J24: Baja
B25: Administración Central SIGVE | C25: HU 2.20 | D25: Como Admin SIGVE quiero editar un item de catálogo para actualizar su información | E25: 2 | F25: 2 | G25: 1.0 | H25: 3 | I25: 1.3 | J25: Media
B26: Administración Central SIGVE | C26: HU 2.21 | D26: Como Admin SIGVE quiero eliminar un item de catálogo para mantener solo opcioens vigentes | E26: 3 | F26: 2 | G26: 1.0 | H26: 1 | I26: 6.0 | J26: Alta
B27: Administración Central SIGVE | C27: HU 2.22 | D27: Como Admin SIGVE quiero crear un usuario con cualquier rol para dar acceso a nuevos miembros del sistema | E27: 5 | F27: 3 | G27: 1.0 | H27: 5 | I27: 3.0 | J27: Alta
B28: Administración Central SIGVE | C28: HU 2.23 | D28: Como Admin SIGVE quier gestionar todos los usuarios del sistema para controlar accesos y roles | E28: 5 | F28: 3 | G28: 1.0 | H28: 5 | I28: 3.0 | J28: Alta
B29: Administración Central SIGVE | C29: HU 2.24 | D29: Como Admin SIGVE quiero editar información de cualquier usuario para actualizar sus datos o cambiar su rol | E29: 5 | F29: 3 | G29: 0.8 | H29: 5 | I29: 2.4 | J29: Media
B30: Administración Central SIGVE | C30: HU 2.25 | D30: Como Admin SIGVE quiero desactivar o activar usuarios para controlar accesos sin eliminar cuentas | E30: 1 | F30: 3 | G30: 1.0 | H30: 6 | I30: 0.5 | J30: Baja
B31: Administración Central SIGVE | C31: HU 2.26 | D31: Como Admin SIGVE quiero eliminar permanentemente un usuario para remover cuentas que ya no se necesitan | E31: 2 | F31: 3 | G31: 1.0 | H31: 3 | I31: 2.0 | J31: Media
B32: Administración Central SIGVE | C32: HU 2.27 | D32: Como Admin SIGVE quiero crear un tipo de solicitud con esquema de formulario dinámico para que los talleres puedan solicitar diferentes tipos de recursos | E32: 7 | F32: 3 | G32: 0.5 | H32: 4 | I32: 2.6 | J32: Media
B33: Administración Central SIGVE | C33: HU 2.28 | D33: Como Admin SIGVE quiero gestionar los tipos de solicitudes configurables para permitir que talleres soliciten diferentes tipos de datos | E33: 3 | F33: 3 | G33: 1.0 | H33: 5 | I33: 1.8 | J33: Media
B34: Administración Central SIGVE | C34: HU 2.29 | D34: Como Admin SIGVE quiero editar un tipo de solicitud para actualizar su configuración | E34: 1 | F34: 5 | G34: 0.8 | H34: 5 | I34: 0.8 | J34: Baja
B35: Administración Central SIGVE | C35: HU 2.30 | D35: Como Admin SIGVE quiero eliminar un tipo de solicitud para mantener solo tipos vigentes | E35: 3 | F35: 2 | G35: 1.0 | H35: 3 | I35: 2.0 | J35: Media
B36: Administración Central SIGVE | C36: HU 2.31 | D36: Como Admin SIGVE quiero ver un centro de solicitudes con pestañas por estado para gestionar solicitudes de talleres de forma organizada | E36: 6 | F36: 3 | G36: 1.0 | H36: 8 | I36: 2.25 | J36: Media
B37: Administración Central SIGVE | C37: HU 2.32 | D37: Como Admin SIGVE quiero aprobar una solicitud de taller para informar la creación del recurso solicitado en el sistema | E37: 8 | F37: 3 | G37: 1.0 | H37: 5 | I37: 4.8 | J37: Alta
B38: Administración Central SIGVE | C38: HU 2.33 | D38: Como Admin SIGVE quiero rechazar una solicitud enviando un motivo para denegar solicitudes que no proceden | E38: 8 | F38: 2 | G38: 1.0 | H38: 3 | I38: 5.33 | J38: Alta
B39: Administración Central SIGVE | C39: HU 2.34 | D39: Como Admin SIGVE quiero gestionar el catálogo de vehículos del sistema para poder ver el listado, filtrar y registrar nuevos vehículos. | E39: 10 | F39: 2 | G39: 1.0 | H39: 8 | I39: 2.5 | J39: Media
B40: Gestión de Taller de Mantención | C40: HU 3.1 | D40: Como usuario del taller quiero visualizar un dashboard con estadisticas del taller para tener una visión general del trabajo | E40: 6 | F40: 2 | G40: 0.8 | H40: 10 | I40: 0.96 | J40: Media
B41: Gestión de Taller de Mantención | C41: HU 3.2 | D41: Como usuario del taller quiero crear una orden de mantención de forma rápida para registrar vehículos que ingresan al taller | E41: 10 | F41: 3 | G41: 1.0 | H41: 5 | I41: 6.0 | J41: Alta
B42: Gestión de Taller de Mantención | C42: HU 3.3 | D42: Como usuario del taller quiero ver el listado de órdenes de mantención para gestionar el trabajo del taller | E42: 8 | F42: 2 | G42: 1.0 | H42: 3 | I42: 5.33 | J42: Alta
...

Sheet Tareas
B3: Tareas
B4: Épica | C4: Historia de Usuario | D4: ID_Historia | E4: ID_Tarea | F4: Tarea | G4: Sprint | H4: Estado
B5: No Aplica | C5: No Aplica | D5: No Aplica | E5: CONF_01 | F5: Crear un repositorio en GitHub para trabajar ambas aplicaciones (Web y Móvil) | G5: Sprint 0 | H5: Finalizada
B6: No Aplica | C6: No Aplica | D6: No Aplica | E6: CONF_02 | F6: Crear el proyecto en Django | G6: Sprint 0 | H6: Finalizada
B7: No Aplica | C7: No Aplica | D7: No Aplica | E7: CONF_03 | F7: Configurar entornos virtuales de Python (venv) | G7: Sprint 0 | H7: Finalizada
B8: No Aplica | C8: No Aplica | D8: No Aplica | E8: CONF_04 | F8: Crear el proyecto en Supabase | G8: Sprint 0 | H8: Finalizada
B9: No Aplica | C9: No Aplica | D9: No Aplica | E9: CONF_05 | F9: Definir el modelo de datos v1 para la base de datos general del sistema | G9: Sprint 0 | H9: Finalizada
B10: No Aplica | C10: No Aplica | D10: No Aplica | E10: CONF_06 | F10: Crear el esquema inicial de la base de datos (tablas principales: Usuarios, Vehiculos, Talleres, Roles) | G10: Sprint 0 | H10: Finalizada
B11: No Aplica | C11: No Aplica | D11: No Aplica | E11: CONF_07 | F11: Establecer la conexión con la base de datos de Supabase (Django) | G11: Sprint 0 | H11: Finalizada
B12: No Aplica | C12: No Aplica | D12: No Aplica | E12: CONF_08 | F12: Crear el proyecto en Android Studio con Kotlin | G12: Sprint 0 | H12: Finalizada
B13: No Aplica | C13: No Aplica | D13: No Aplica | E13: CONF_09 | F13: Configurar las dependencias de Jetpack Compose. | G13: Sprint 0 | H13: Finalizada
B14: =IFERROR(_xlfn.XLOOKUP(D14,'Historias de Usuario'!C:C,'Historias de Usuario'!B:B, "Selecciona una historia"), "") -> Autenticación y Acceso | C14: =IFERROR(_xlfn.XLOOKUP(D14,'Historias de Usuario'!C:C,'Historias de Usuario'!D:D, "Selecciona una historia"), "") -> Como usuario del sistema quiero poder iniciar y cerrar sesión para acceder a las funcionalidades según mi rol | D14: HU 1.1 | E14: AUTH_001 | F14: Habilitar autenticación con email y contraseña en Supabase | G14: Sprint 1 | H14: Finalizada
B15: Autenticación y Acceso | C15: =IFERROR(_xlfn.XLOOKUP(D15,'Historias de Usuario'!C:C,'Historias de Usuario'!D:D, "Selecciona una historia"), "") -> Como usuario del sistema quiero poder iniciar y cerrar sesión para acceder a las funcionalidades según mi rol | D15: HU 1.1 | E15: WEB_001 | F15: Crear formulario de inicio de sesión con campos 'email' y 'contraseña' | G15: Sprint 1 | H15: Finalizada
B16: =IFERROR(_xlfn.XLOOKUP(D16,'Historias de Usuario'!C:C,'Historias de Usuario'!B:B, "Selecciona una historia"), "") -> Autenticación y Acceso | C16: =IFERROR(_xlfn.XLOOKUP(D16,'Historias de Usuario'!C:C,'Historias de Usuario'!D:D, "Selecciona una historia"), "") -> Como usuario del sistema quiero poder iniciar y cerrar sesión para acceder a las funcionalidades según mi rol | D16: HU 1.1 | E16: WEB_002 | F16: Crear botón "Iniciar Sesión" para enviar credenciales | G16: Sprint 1 | H16: Finalizada
B17: =IFERROR(_xlfn.XLOOKUP(D17,'Historias de Usuario'!C:C,'Historias de Usuario'!B:B, "Selecciona una historia"), "") -> Autenticación y Acceso | C17: =IFERROR(_xlfn.XLOOKUP(D17,'Historias de Usuario'!C:C,'Historias de Usuario'!D:D, "Selecciona una historia"), "") -> Como usuario del sistema quiero poder iniciar y cerrar sesión para acceder a las funcionalidades según mi rol | D17: HU 1.1 | E17: WEB_003 | F17: Validar que el campo "email" tenga formato de correo válido | G17: Sprint 1 | H17: Finalizada
B18: =IFERROR(_xlfn.XLOOKUP(D18,'Historias de Usuario'!C:C,'Historias de Usuario'!B:B, "Selecciona una historia"), "") -> Autenticación y Acceso | C18: =IFERROR(_xlfn.XLOOKUP(D18,'Historias de Usuario'!C:C,'Historias de Usuario'!D:D, "Selecciona una historia"), "") -> Como usuario del sistema quiero poder iniciar y cerrar sesión para acceder a las funcionalidades según mi rol | D18: HU 1.1 | E18: WEB_004 | F18: Validar que el campo "contraseña" no esté vacío | G18: Sprint 1 | H18: Finalizada
B19: =IFERROR(_xlfn.XLOOKUP(D19,'Historias de Usuario'!C:C,'Historias de Usuario'!B:B, "Selecciona una historia"), "") -> Autenticación y Acceso | C19: =IFERROR(_xlfn.XLOOKUP(D19,'Historias de Usuario'!C:C,'Historias de Usuario'!D:D, "Selecciona una historia"), "") -> Como usuario del sistema quiero poder iniciar y cerrar sesión para acceder a las funcionalidades según mi rol | D19: HU 1.1 | E19: WEB_005 | F19: Mostrar mensaje de error si las credenciales son incorrectas | G19: Sprint 1 | H19: Finalizada
B20: =IFERROR(_xlfn.XLOOKUP(D20,'Historias de Usuario'!C:C,'Historias de Usuario'!B:B, "Selecciona una historia"), "") -> Autenticación y Acceso | C20: =IFERROR(_xlfn.XLOOKUP(D20,'Historias de Usuario'!C:C,'Historias de Usuario'!D:D, "Selecciona una historia"), "") -> Como usuario del sistema quiero poder iniciar y cerrar sesión para acceder a las funcionalidades según mi rol | D20: HU 1.1 | E20: WEB_006 | F20: Mostrar mensaje de bienvenida al iniciar sesión exitosamente | G20: Sprint 1 | H20: Finalizada
B21: =IFERROR(_xlfn.XLOOKUP(D21,'Historias de Usuario'!C:C,'Historias de Usuario'!B:B, "Selecciona una historia"), "") -> Autenticación y Acceso | C21: =IFERROR(_xlfn.XLOOKUP(D21,'Historias de Usuario'!C:C,'Historias de Usuario'!D:D, "Selecciona una historia"), "") -> Como usuario del sistema quiero poder iniciar y cerrar sesión para acceder a las funcionalidades según mi rol | D21: HU 1.1 | E21: WEB_007 | F21: Redirigir al usuario según su rol (Super Admin, Admin SIGVE, Admin Taller, Mecánico, Jefe Cuartel) | G21: Sprint 1 | H21: Finalizada
B22: =IFERROR(_xlfn.XLOOKUP(D22,'Historias de Usuario'!C:C,'Historias de Usuario'!B:B, "Selecciona una historia"), "") -> Autenticación y Acceso | C22: =IFERROR(_xlfn.XLOOKUP(D22,'Historias de Usuario'!C:C,'Historias de Usuario'!D:D, "Selecciona una historia"), "") -> Como usuario del sistema quiero poder iniciar y cerrar sesión para acceder a las funcionalidades según mi rol | D22: HU 1.1 | E22: WEB_008 | F22: Implementar botón "Olvidé mi contraseña" en el formulario de login | G22: Sprint 1 | H22: Sin Iniciar
B23: =IFERROR(_xlfn.XLOOKUP(D23,'Historias de Usuario'!C:C,'Historias de Usuario'!B:B, "Selecciona una historia"), "") -> Autenticación y Acceso | C23: =IFERROR(_xlfn.XLOOKUP(D23,'Historias de Usuario'!C:C,'Historias de Usuario'!D:D, "Selecciona una historia"), "") -> Como usuario del sistema quiero poder iniciar y cerrar sesión para acceder a las funcionalidades según mi rol | D23: HU 1.1 | E23: WEB_009 | F23: Crear botón 'Cerrar Sesión' en la barra de navegación | G23: Sprint 1 | H23: Finalizada
B24: =IFERROR(_xlfn.XLOOKUP(D24,'Historias de Usuario'!C:C,'Historias de Usuario'!B:B, "Selecciona una historia"), "") -> Autenticación y Acceso | C24: =IFERROR(_xlfn.XLOOKUP(D24,'Historias de Usuario'!C:C,'Historias de Usuario'!D:D, "Selecciona una historia"), "") -> Como usuario del sistema quiero poder iniciar y cerrar sesión para acceder a las funcionalidades según mi rol | D24: HU 1.1 | E24: WEB_010 | F24: Mostrar mensaje informativo al cerrar sesión | G24: Sprint 1 | H24: Finalizada
B25: =IFERROR(_xlfn.XLOOKUP(D25,'Historias de Usuario'!C:C,'Historias de Usuario'!B:B, "Selecciona una historia"), "") -> Autenticación y Acceso | C25: =IFERROR(_xlfn.XLOOKUP(D25,'Historias de Usuario'!C:C,'Historias de Usuario'!D:D, "Selecciona una historia"), "") -> Como usuario del sistema quiero poder iniciar y cerrar sesión para acceder a las funcionalidades según mi rol | D25: HU 1.1 | E25: WEB_011 | F25: Implementar página de 'No Autorizado' con código HTTP 403 cuando el usuario no tiene permisos | G25: Sprint 1 | H25: Finalizada
B26: =IFERROR(_xlfn.XLOOKUP(D26,'Historias de Usuario'!C:C,'Historias de Usuario'!B:B, "Selecciona una historia"), "") -> Autenticación y Acceso | C26: =IFERROR(_xlfn.XLOOKUP(D26,'Historias de Usuario'!C:C,'Historias de Usuario'!D:D, "Selecciona una historia"), "") -> Como usuario del sistema quiero poder iniciar y cerrar sesión para acceder a las funcionalidades según mi rol | D26: HU 1.1 | E26: APP_001 | F26: Crear formulario de inicio de sesión con campos 'email' y 'contraseña' | G26: Sprint 1 | H26: Finalizada
B27: =IFERROR(_xlfn.XLOOKUP(D27,'Historias de Usuario'!C:C,'Historias de Usuario'!B:B, "Selecciona una historia"), "") -> Autenticación y Acceso | C27: =IFERROR(_xlfn.XLOOKUP(D27,'Historias de Usuario'!C:C,'Historias de Usuario'!D:D, "Selecciona una historia"), "") -> Como usuario del sistema quiero poder iniciar y cerrar sesión para acceder a las funcionalidades según mi rol | D27: HU 1.1 | E27: APP_002 | F27: Crear botón "Iniciar Sesión" para enviar credenciales | G27: Sprint 1 | H27: Finalizada
... B124: =IFERROR(_xlfn.XLOOKUP(D124,'Historias de Usuario'!C:C,'Historias de Usuario'!B:B, "Selecciona una historia"), "") -> Administración Central SIGVE | C124: =IFERROR(_xlfn.XLOOKUP(D124,'Historias de Usuario'!C:C,'Historias de Usuario'!D:D, "Selecciona una historia"), "") -> Como Admin SIGVE quiero crear un proveedor global para que todos los talleres puedan usarlo | D124: HU 2.14 | E124: WEB_101 | F124: Campo opcional 'Email' con validación | G124: Sprint 3 | H124: Finalizada
B125: Administración Central SIGVE | C125: =IFERROR(_xlfn.XLOOKUP(T_Tarea[[#This Row],[ID_Historia]],'Historias de Usuario'!C:C,'Historias de Usuario'!D:D, "Selecciona una historia"), "") -> Como Admin SIGVE quiero crear un proveedor global para que todos los talleres puedan usarlo | D125: HU 2.14 | E125: WEB_102 | F125: Botón "Guardar" y "Cancelar" | G125: Sprint 3 | H125: Finalizada
B126: =IFERROR(_xlfn.XLOOKUP(D126,'Historias de Usuario'!C:C,'Historias de Usuario'!B:B, "Selecciona una historia"), "") -> Administración Central SIGVE | C126: =IFERROR(_xlfn.XLOOKUP(D126,'Historias de Usuario'!C:C,'Historias de Usuario'!D:D, "Selecciona una historia"), "") -> Como Admin SIGVE quiero crear un proveedor global para que todos los talleres puedan usarlo | D126: HU 2.14 | E126: WEB_103 | F126: Mensaje de éxito al crear | G126: Sprint 3 | H126: Finalizada
B127: =IFERROR(_xlfn.XLOOKUP(D127,'Historias de Usuario'!C:C,'Historias de Usuario'!B:B, "Selecciona una historia"), "") -> Administración Central SIGVE | C127: =IFERROR(_xlfn.XLOOKUP(D127,'Historias de Usuario'!C:C,'Historias de Usuario'!D:D, "Selecciona una historia"), "") -> Como Admin SIGVE quiero gestionar el catálogo de proveedores globalres para que esten disponibles parar todos los talleres | D127: HU 2.15 | E127: WEB_104 | F127: Tabla con listado de proveedores (nombre, RUT, dirección, teléfono, email) | G127: Sprint 3 | H127: Finalizada
B128: =IFERROR(_xlfn.XLOOKUP(D128,'Historias de Usuario'!C:C,'Historias de Usuario'!B:B, "Selecciona una historia"), "") -> Administración Central SIGVE | C128: =IFERROR(_xlfn.XLOOKUP(D128,'Historias de Usuario'!C:C,'Historias de Usuario'!D:D, "Selecciona una historia"), "") -> Como Admin SIGVE quiero gestionar el catálogo de proveedores globalres para que esten disponibles parar todos los talleres | D128: HU 2.15 | E128: WEB_105 | F128: Botón "Crear Proveedor" para abrir formulario modal de creación de proveedores | G128: Sprint 3 | H128: Finalizada
B129: =IFERROR(_xlfn.XLOOKUP(D129,'Historias de Usuario'!C:C,'Historias de Usuario'!B:B, "Selecciona una historia"), "") -> Administración Central SIGVE | C129: =IFERROR(_xlfn.XLOOKUP(D129,'Historias de Usuario'!C:C,'Historias de Usuario'!D:D, "Selecciona una historia"), "") -> Como Admin SIGVE quiero gestionar el catálogo de proveedores globalres para que esten disponibles parar todos los talleres | D129: HU 2.15 | E129: WEB_106 | F129: Botón "Editar" en cada fila que abre formulario modal en "Modo Edición" | G129: Sprint 3 | H129: Finalizada
B130: =IFERROR(_xlfn.XLOOKUP(D130,'Historias de Usuario'!C:C,'Historias de Usuario'!B:B, "Selecciona una historia"), "") -> Administración Central SIGVE | C130: =IFERROR(_xlfn.XLOOKUP(D130,'Historias de Usuario'!C:C,'Historias de Usuario'!D:D, "Selecciona una historia"), "") -> Como Admin SIGVE quiero gestionar el catálogo de proveedores globalres para que esten disponibles parar todos los talleres | D130: HU 2.15 | E130: WEB_107 | F130: Botón "Eliminar" en cada fila con confirmación | G130: Sprint 3 | H130: Finalizada
B131: =IFERROR(_xlfn.XLOOKUP(D131,'Historias de Usuario'!C:C,'Historias de Usuario'!B:B, "Selecciona una historia"), "") -> Administración Central SIGVE | C131: =IFERROR(_xlfn.XLOOKUP(D131,'Historias de Usuario'!C:C,'Historias de Usuario'!D:D, "Selecciona una historia"), "") -> Como Admin SIGVE quiero gestionar el catálogo de proveedores globalres para que esten disponibles parar todos los talleres | D131: HU 2.15 | E131: WEB_108 | F131: Mensaje "No hay proveedores registrados" cuando la lista está vacía | G131: Sprint 3 | H131: Finalizada
B132: =IFERROR(_xlfn.XLOOKUP(D132,'Historias de Usuario'!C:C,'Historias de Usuario'!B:B, "Selecciona una historia"), "") -> Administración Central SIGVE | C132: =IFERROR(_xlfn.XLOOKUP(D132,'Historias de Usuario'!C:C,'Historias de Usuario'!D:D, "Selecciona una historia"), "") -> Como Admin SIGVE quiero editar un proveedor global para mantener sus datos actualizados | D132: HU 2.16 | E132: WEB_109 | F132: Modal "Editar Proveedor" con datos pre-cargados | G132: Sprint 3 | H132: Finalizada
B133: =IFERROR(_xlfn.XLOOKUP(D133,'Historias de Usuario'!C:C,'Historias de Usuario'!B:B, "Selecciona una historia"), "") -> Administración Central SIGVE | C133: =IFERROR(_xlfn.XLOOKUP(D133,'Historias de Usuario'!C:C,'Historias de Usuario'!D:D, "Selecciona una historia"), "") -> Como Admin SIGVE quiero editar un proveedor global para mantener sus datos actualizados | D133: HU 2.16 | E133: WEB_110 | F133: Permitir edición de todos los campos | G133: Sprint 3 | H133: Finalizada
B134: =IFERROR(_xlfn.XLOOKUP(D134,'Historias de Usuario'!C:C,'Historias de Usuario'!B:B, "Selecciona una historia"), "") -> Administración Central SIGVE | C134: =IFERROR(_xlfn.XLOOKUP(D134,'Historias de Usuario'!C:C,'Historias de Usuario'!D:D, "Selecciona una historia"), "") -> Como Admin SIGVE quiero editar un proveedor global para mantener sus datos actualizados | D134: HU 2.16 | E134: WEB_111 | F134: Botón "Actualizar" | G134: Sprint 3 | H134: Finalizada
B135: =IFERROR(_xlfn.XLOOKUP(D135,'Historias de Usuario'!C:C,'Historias de Usuario'!B:B, "Selecciona una historia"), "") -> Administración Central SIGVE | C135: =IFERROR(_xlfn.XLOOKUP(D135,'Historias de Usuario'!C:C,'Historias de Usuario'!D:D, "Selecciona una historia"), "") -> Como Admin SIGVE quiero editar un proveedor global para mantener sus datos actualizados | D135: HU 2.16 | E135: WEB_112 | F135: Mensaje de éxito al actualizar | G135: Sprint 3 | H135: Finalizada
B136: =IFERROR(_xlfn.XLOOKUP(D136,'Historias de Usuario'!C:C,'Historias de Usuario'!B:B, "Selecciona una historia"), "") -> Administración Central SIGVE | C136: =IFERROR(_xlfn.XLOOKUP(D136,'Historias de Usuario'!C:C,'Historias de Usuario'!D:D, "Selecciona una historia"), "") -> Como Admin SIGVE quiero eliminar un proveedor para mantener solo proveedores activos | D136: HU 2.17 | E136: WEB_113 | F136: Modal de confirmación antes de eliminar | G136: Sprint 3 | H136: Finalizada
B137: =IFERROR(_xlfn.XLOOKUP(D137,'Historias de Usuario'!C:C,'Historias de Usuario'!B:B, "Selecciona una historia"), "") -> Administración Central SIGVE | C137: =IFERROR(_xlfn.XLOOKUP(D137,'Historias de Usuario'!C:C,'Historias de Usuario'!D:D, "Selecciona una historia"), "") -> Como Admin SIGVE quiero eliminar un proveedor para mantener solo proveedores activos | D137: HU 2.17 | E137: WEB_114 | F137: Mensaje de éxito al eliminar | G137: Sprint 3 | H137: Finalizada
... B583: =IFERROR(_xlfn.XLOOKUP(D583,'Historias de Usuario'!C:C,'Historias de Usuario'!B:B, "Selecciona una historia"), "") -> Gestión de Cuartel de Bomberos | C583: =IFERROR(_xlfn.XLOOKUP(D583,'Historias de Usuario'!C:C,'Historias de Usuario'!D:D, "Selecciona una historia"), "") -> Como Jefe Cuartel quiero eliminar cuentas de usuarios para mantener un control de los usuarios que tienen acceso al sistema | D583: HU 4.14 | E583: WEB_560 | F583: Mensaje de error si el vehículo tiene datos asociados y no se puede eliminar | G583: Sprint 6 | H583: Finalizada
...

Sheet Sprint
C2: Para ver los demas Sprints cambiar casilla de abajo
B3: Tablero Sprint: | C3: Sprint 7
B5: Epica | C5: Historia | D5: ID_Historia | E5: ID_Tarea | F5: Tarea | G5: Estado
B6: {=_xlfn._xlws.FILTER(_xlfn.CHOOSECOLS(T_Tarea[], 1, 2, 3, 4, 5, 7), T_Tarea[Sprint] = C3)} -> Gestión de Cuartel de Bomberos | C6: Como Jefe de Cuartel quiero ver un dashboard con estadísticas y resumen de mis vehículos para tener una visión general del estado operativo del cuartel | D6: HU 5.1 | E6: APP_010 | F6: Crear pantalla principal del dashboard | G6: Finalizada
B7: Gestión de Cuartel de Bomberos | C7: Como Jefe de Cuartel quiero ver un dashboard con estadísticas y resumen de mis vehículos para tener una visión general del estado operativo del cuartel | D7: HU 5.1 | E7: APP_011 | F7: Implementar tarjetas de estadísticas del dashboard | G7: Finalizada
B8: Gestión de Cuartel de Bomberos | C8: Como Jefe de Cuartel quiero ver un dashboard con estadísticas y resumen de mis vehículos para tener una visión general del estado operativo del cuartel | D8: HU 5.1 | E8: APP_012 | F8: Implementar sistema de alertas en dashboard | G8: Finalizada
B9: Gestión de Cuartel de Bomberos | C9: Como Jefe de Cuartel quiero ver un dashboard con estadísticas y resumen de mis vehículos para tener una visión general del estado operativo del cuartel | D9: HU 5.1 | E9: APP_013 | F9: Implementar búsqueda de vehículos en dashboard | G9: Finalizada
B10: Gestión de Cuartel de Bomberos | C10: Como Jefe de Cuartel quiero ver un dashboard con estadísticas y resumen de mis vehículos para tener una visión general del estado operativo del cuartel | D10: HU 5.1 | E10: APP_014 | F10: Implementar filtros por estado en dashboard | G10: Finalizada
B11: Gestión de Cuartel de Bomberos | C11: Como Jefe de Cuartel quiero ver un dashboard con estadísticas y resumen de mis vehículos para tener una visión general del estado operativo del cuartel | D11: HU 5.1 | E11: APP_015 | F11: Implementar lista de vehículos en dashboard | G11: Finalizada
B12: Gestión de Cuartel de Bomberos | C12: Como Jefe de Cuartel quiero ver el listado completo de vehículos para tener una vista más detallada y navegar al historial de cada vehículo | D12: HU 5.2 | E12: APP_016 | F12: Crear pantalla de listado completo de vehículos | G12: Finalizada
B13: Gestión de Cuartel de Bomberos | C13: Como Jefe de Cuartel quiero ver el listado completo de vehículos para tener una vista más detallada y navegar al historial de cada vehículo | D13: HU 5.2 | E13: APP_017 | F13: Implementar visualización de vehículos en Lista | G13: Finalizada
B14: Gestión de Cuartel de Bomberos | C14: Como Jefe de Cuartel quiero ver el listado completo de vehículos para tener una vista más detallada y navegar al historial de cada vehículo | D14: HU 5.2 | E14: APP_018 | F14: Implementar búsqueda y filtros en lista de vehículos | G14: Finalizada
B15: Gestión de Cuartel de Bomberos | C15: Como Jefe de Cuartel quiero ver el listado completo de vehículos para tener una vista más detallada y navegar al historial de cada vehículo | D15: HU 5.2 | E15: APP_019 | F15: Implementar visualización de cambios de estado | G15: Finalizada
B16: Gestión de Taller de Mantención | C16: Como Admin Taller o Mecánico quiero ver un dashboard con resumen del taller para tener una visión general del estado de las mantenciones | D16: HU 5.3 | E16: APP_020 | F16: Crear pantalla principal del dashboard de taller | G16: Finalizada
B17: Gestión de Taller de Mantención | C17: Como Admin Taller o Mecánico quiero ver un dashboard con resumen del taller para tener una visión general del estado de las mantenciones | D17: HU 5.3 | E17: APP_021 | F17: Implementar tarjetas principales de estadísticas | G17: Finalizada
B18: Gestión de Taller de Mantención | C18: Como Admin Taller o Mecánico quiero ver un dashboard con resumen del taller para tener una visión general del estado de las mantenciones | D18: HU 5.3 | E18: APP_022 | F18: Implementar acciones rápidas en dashboard | G18: Finalizada
... B47: Gestión de Taller de Mantención | C47: Como Admin Taller o Mecánico quiero ver un resumen del inventario del taller para conocer el estado general del inventario | D47: HU 5.5 | E47: APP_051 | F47: Implementar gestión crud de inventario | G47: Finalizada

Sheet Estadísticas Sprints
B4: Sprint 0 | E4: Sprint 1 | H4: Tareas Finalizadas | I4: =SUM(C5,F5,C11,F11,C17,F17,C23) -> 542 | J4: =_xlfn.PERCENTOF(I4,$I$4:$I$7) -> 0.93609672
B5: Finalizada | C5: =COUNTIFS(T_Tarea[Sprint], B4, T_Tarea[Estado], B5) -> 9 | E5: Finalizada | F5: =COUNTIFS(T_Tarea[Sprint], E4, T_Tarea[Estado], E5) -> 19 | H5: Tareas En Proceso | I5: =SUM(C6,F6,C12,F12,C18,F18,C24) -> 22 | J5: =_xlfn.PERCENTOF(I5,$I$4:$I$7) -> 0.037996546
B6: En Proceso | C6: =COUNTIFS(T_Tarea[Sprint], B4, T_Tarea[Estado], B6) -> 0 | E6: En Proceso | F6: =COUNTIFS(T_Tarea[Sprint], E4, T_Tarea[Estado], E6) -> 0 | H6: Tareas Sin Iniciar | I6: =SUM(C7,F7,C13,F13,C19,F19,C25) -> 2 | J6: =_xlfn.PERCENTOF(I6,$I$4:$I$7) -> 0.0034542314
B7: Sin Iniciar | C7: =COUNTIFS(T_Tarea[Sprint], B4, T_Tarea[Estado], B7) -> 0 | E7: Sin Iniciar | F7: =COUNTIFS(T_Tarea[Sprint], E4, T_Tarea[Estado], E7) -> 2 | H7: Tareas Postergadas | I7: =SUM(C8,F8,C14,F14,C20,F20,C26) -> 13 | J7: =_xlfn.PERCENTOF(I7,$I$4:$I$7) -> 0.022452504
B8: Postergada | C8: =COUNTIFS(T_Tarea[Sprint], B4, T_Tarea[Estado], B8) -> 0 | E8: Postergada | F8: =COUNTIFS(T_Tarea[Sprint], E4, T_Tarea[Estado], E8) -> 0
B10: Sprint 2 | E10: Sprint 3
B11: Finalizada | C11: =COUNTIFS(T_Tarea[Sprint], B10, T_Tarea[Estado], B11) -> 42 | E11: Finalizada | F11: =COUNTIFS(T_Tarea[Sprint], E10, T_Tarea[Estado], E11) -> 161
B12: En Proceso | C12: =COUNTIFS(T_Tarea[Sprint], B10, T_Tarea[Estado], B12) -> 0 | E12: En Proceso | F12: =COUNTIFS(T_Tarea[Sprint], E10, T_Tarea[Estado], E12) -> 0
B13: Sin Iniciar | C13: =COUNTIFS(T_Tarea[Sprint], B10, T_Tarea[Estado], B13) -> 0 | E13: Sin Iniciar | F13: =COUNTIFS(T_Tarea[Sprint], E10, T_Tarea[Estado], E13) -> 0
B14: Postergada | C14: =COUNTIFS(T_Tarea[Sprint], B10, T_Tarea[Estado], B14) -> 0 | E14: Postergada | F14: =COUNTIFS(T_Tarea[Sprint], E10, T_Tarea[Estado], E14) -> 10
B16: Sprint 4 | E16: Sprint 5
B17: Finalizada | C17: =COUNTIFS(T_Tarea[Sprint], B16, T_Tarea[Estado], B17) -> 67 | E17: Finalizada | F17: =COUNTIFS(T_Tarea[Sprint], E16, T_Tarea[Estado], E17) -> 131
B18: En Proceso | C18: =COUNTIFS(T_Tarea[Sprint], B16, T_Tarea[Estado], B18) -> 0 | E18: En Proceso | F18: =COUNTIFS(T_Tarea[Sprint], E16, T_Tarea[Estado], E18) -> 0
B19: Sin Iniciar | C19: =COUNTIFS(T_Tarea[Sprint], B16, T_Tarea[Estado], B19) -> 0 | E19: Sin Iniciar | F19: =COUNTIFS(T_Tarea[Sprint], E16, T_Tarea[Estado], E19) -> 0
B20: Postergada | C20: =COUNTIFS(T_Tarea[Sprint], B16, T_Tarea[Estado], B20) -> 3 | E20: Postergada | F20: =COUNTIFS(T_Tarea[Sprint], E16, T_Tarea[Estado], E20) -> 0
B22: Sprint 6
B23: Finalizada | C23: =COUNTIFS(T_Tarea[Sprint], B22, T_Tarea[Estado], B23) -> 113
B24: En Proceso | C24: =COUNTIFS(T_Tarea[Sprint], B22, T_Tarea[Estado], B24) -> 22
B25: Sin Iniciar | C25: =COUNTIFS(T_Tarea[Sprint], B22, T_Tarea[Estado], B25) -> 0
B26: Postergada | C26: =COUNTIFS(T_Tarea[Sprint], B22, T_Tarea[Estado], B26) -> 0

Sheet Configuración
C4: Responsables | D4: Estados_HU | E4: Prioridades | F4: Estados | G4: Sprints
C5: Christian | D5: Pendiente | E5: Alta | F5: Finalizada | G5: Sprint 0
C6: Matías | D6: En Desarrollo | E6: Media | F6: En Proceso | G6: Sprint 1
C7: Sebastián | D7: En QA | E7: Baja | F7: Sin Iniciar | G7: Sprint 2
D8: Finalizada | F8: Postergada | G8: Sprint 3
G9: Sprint 4
G10: Sprint 5
G11: Sprint 6
G12: Sprint 7
